<?xml version="1.0"?>
<robot name="right_hand">
<!-- 后续的link、joint等定义将在这里添加 -->
<link
    name="right_hand_base_link">
    <inertial>
      <origin
        xyz="0.00391160608884322 0.00448556353730908 0.0340831709778913"
        rpy="0 0 0" />
      <mass
        value="0.05804100477032" />
      <inertia
        ixx="8.91313181976465E-05"
        ixy="-6.04640652659731E-06"
        ixz="3.71821689962293E-06"
        iyy="5.49150596507255E-05"
        iyz="-2.70983228107086E-06"
        izz="5.61534622447738E-05" />
    </inertial>
    <visual>
      <origin
        xyz="0 0 0"
        rpy="0 0 0" />
      <geometry>
        <mesh
          filename="../meshes/right_hand_base_link.STL" />
      </geometry>
      <material
        name="">
        <color
          rgba="0.752941176470588 0.752941176470588 0.752941176470588 1" />
      </material>
    </visual>
    <collision>
      <origin
        xyz="0 0 0"
        rpy="0 0 0" />
      <geometry>
        <mesh
          filename="../meshes/right_hand_base_link.STL" />
      </geometry>
    </collision>
  </link>


  <link
    name="r_index_Link">
    <inertial>
      <origin
        xyz="1.40772269751482E-06 0.000694750558183271 -0.00514190536442029"
        rpy="0 0 0" />
      <mass
        value="0.00431903565449312" />
      <inertia
        ixx="1.36153741961389E-06"
        ixy="9.7926688192208E-11"
        ixz="4.65697331197809E-12"
        iyy="2.52419403692596E-07"
        iyz="-1.32210382096263E-07"
        izz="1.38757776970107E-06" />
    </inertial>
    <visual>
      <origin
        xyz="0 0 0"
        rpy="0 0 0" />
      <geometry>
        <mesh
          filename="../meshes/r_index_Link.STL" />
      </geometry>
      <material
        name="">
        <color
          rgba="0.752941176470588 0.752941176470588 0.752941176470588 1" />
      </material>
    </visual>
    <collision>
      <origin
        xyz="0 0 0"
        rpy="0 0 0" />
      <geometry>
        <mesh
          filename="../meshes/r_index_Link.STL" />
      </geometry>
    </collision>
  </link>
  <joint
    name="index_joint_Link_r"
    type="fixed">
    <origin
      xyz="-0.0103822553151064 0.0375051922308144 0.0613093829703847"
      rpy="1.65806266442309 0 1.5707963267949" />
    <parent
      link="right_hand_base_link" />
    <child
      link="r_index_Link" />
    <axis
      xyz="0 0 0" />
  </joint>
  <link
    name="r_index_Link1">
    <inertial>
      <origin
        xyz="3.36279767296221E-08 -0.000949758546197055 -0.00979761945346892"
        rpy="0 0 0" />
      <mass
        value="0.000753716554216806" />
      <inertia
        ixx="4.38605309747152E-08"
        ixy="-3.33324396352921E-14"
        ixz="-1.25779733473156E-13"
        iyy="9.49698620695859E-08"
        iyz="-2.45771565297734E-09"
        izz="5.93127496812786E-08" />
    </inertial>
    <visual>
      <origin
        xyz="0 0 0"
        rpy="0 0 0" />
      <geometry>
        <mesh
          filename="../meshes/r_index_Link1.STL" />
      </geometry>
      <material
        name="">
        <color
          rgba="0.792156862745098 0.819607843137255 0.933333333333333 1" />
      </material>
    </visual>
    <collision>
      <origin
        xyz="0 0 0"
        rpy="0 0 0" />
      <geometry>
        <mesh
          filename="../meshes/r_index_Link1.STL" />
      </geometry>
    </collision>
  </link>
  <joint
    name="index_joint_Link_r1"
    type="revolute">
    <origin
      xyz="0 0.02627 0.012021"
      rpy="0 0 0" />
    <parent
      link="r_index_Link" />
    <child
      link="r_index_Link1" />
    <axis
      xyz="0 0 -1" />
    <limit
      lower="-0.35"
      upper="0.35"
      effort="0"
      velocity="0" />
  </joint>
  <link
    name="r_index_Link2">
    <inertial>
      <origin
        xyz="0.024856566164087 -0.00646869536322205 -6.14075742498207E-05"
        rpy="0 0 0" />
      <mass
        value="0.00670640144971691" />
      <inertia
        ixx="2.74479460170706E-07"
        ixy="-5.34656147943623E-08"
        ixz="1.86377740407272E-09"
        iyy="1.64928295568456E-06"
        iyz="-4.93690159001492E-10"
        izz="1.53795924684832E-06" />
    </inertial>
    <visual>
      <origin
        xyz="0 0 0"
        rpy="0 0 0" />
      <geometry>
        <mesh
          filename="../meshes/r_index_Link2.STL" />
      </geometry>
      <material
        name="">
        <color
          rgba="0.792156862745098 0.819607843137255 0.933333333333333 1" />
      </material>
    </visual>
    <collision>
      <origin
        xyz="0 0 0"
        rpy="0 0 0" />
      <geometry>
        <mesh
          filename="../meshes/r_index_Link2.STL" />
      </geometry>
    </collision>
  </link>
  <joint
    name="index_joint_Link_r2"
    type="revolute">
    <origin
      xyz="0 0 0"
      rpy="1.5708 0.085664 1.5708" />
    <parent
      link="r_index_Link1" />
    <child
      link="r_index_Link2" />
    <axis
      xyz="0 0 1" />
    <limit
      lower="0"
      upper="1.48"
      effort="0"
      velocity="0" />
  </joint>
  <link
    name="r_index_Link3">
    <inertial>
      <origin
        xyz="0.0118307803985283 -0.00648694607574674 -0.000796162578510826"
        rpy="0 0 0" />
      <mass
        value="0.00348556483804973" />
      <inertia
        ixx="9.92805057586549E-08"
        ixy="2.41258690952191E-08"
        ixz="-5.74560102307089E-09"
        iyy="3.52536489398498E-07"
        iyz="1.97293094024626E-10"
        izz="3.29212834878614E-07" />
    </inertial>
    <visual>
      <origin
        xyz="0 0 0"
        rpy="0 0 0" />
      <geometry>
        <mesh
          filename="../meshes/r_index_Link3.STL" />
      </geometry>
      <material
        name="">
        <color
          rgba="0.792156862745098 0.819607843137255 0.933333333333333 1" />
      </material>
    </visual>
    <collision>
      <origin
        xyz="0 0 0"
        rpy="0 0 0" />
      <geometry>
        <mesh
          filename="../meshes/r_index_Link3.STL" />
      </geometry>
    </collision>
  </link>
  <joint
    name="index_joint_Link_r3"
    type="revolute">
    <origin
      xyz="0.051996 -0.00027708 0"
      rpy="0 0 0.085664" />
    <parent
      link="r_index_Link2" />
    <child
      link="r_index_Link3" />
    <axis
      xyz="0 0 1" />
    <limit
      lower="0"
      upper="1.4"
      effort="0"
      velocity="0" />
  </joint>
  <link
    name="r_index_Link4">
    <inertial>
      <origin
        xyz="0.0113404372697323 -0.00167958619198047 -0.000220244239396365"
        rpy="0 0 0" />
      <mass
        value="0.00286590326282756" />
      <inertia
        ixx="1.43022179569981E-07"
        ixy="1.98729010946548E-08"
        ixz="-6.94917459018936E-09"
        iyy="2.98349815549781E-07"
        iyz="5.48901986574559E-10"
        izz="2.23361577561817E-07" />
    </inertial>
    <visual>
      <origin
        xyz="0 0 0"
        rpy="0 0 0" />
      <geometry>
        <mesh
          filename="../meshes/r_index_Link4.STL" />
      </geometry>
      <material
        name="">
        <color
          rgba="0.792156862745098 0.819607843137255 0.933333333333333 1" />
      </material>
    </visual>
    <collision>
      <origin
        xyz="0 0 0"
        rpy="0 0 0" />
      <geometry>
        <mesh
          filename="../meshes/r_index_Link4.STL" />
      </geometry>
    </collision>
  </link>
  <joint
    name="index_joint_Link_r4"
    type="revolute">
    <origin
      xyz="0.026928 -0.0076747 0"
      rpy="0 0 0" />
    <parent
      link="r_index_Link3" />
    <child
      link="r_index_Link4" />
    <axis
      xyz="0 0 1" />
    <limit
      lower="0"
      upper="1.4"
      effort="0"
      velocity="0" />
  </joint>
  <link
    name="r_index_Link5">
    <inertial>
      <origin
        xyz="0.00181569960563305 -0.00401759470056604 -1.73942399137039E-06"
        rpy="0 0 0" />
      <mass
        value="0.000450710583141384" />
      <inertia
        ixx="1.88812291416615E-08"
        ixy="1.04173783141532E-08"
        ixz="1.05243210031501E-12"
        iyy="2.21563214884092E-08"
        iyz="-4.53245467007608E-12"
        izz="2.55181321608876E-08" />
    </inertial>
    <visual>
      <origin
        xyz="0 0 0"
        rpy="0 0 0" />
      <geometry>
        <mesh
          filename="../meshes/r_index_Link5.STL" />
      </geometry>
      <material
        name="">
        <color
          rgba="0.792156862745098 0.819607843137255 0.933333333333333 1" />
      </material>
    </visual>

    <!-- Add fingertip sphere -->
    <visual>
      <origin xyz="0 0 0" rpy="0 0 0" /> <!-- Positioning the sphere slightly from the tip -->
      <geometry>
        <sphere radius="0.005" /> <!-- Radius of the sphere, 5mm -->
      </geometry>
      <material name="green">
        <color rgba="0 1 0 1" /> <!-- Red color for the fingertip -->
      </material>
    </visual>
  
    <collision>
      <origin
        xyz="0 0 0"
        rpy="0 0 0" />
      <geometry>
        <mesh
          filename="../meshes/r_index_Link5.STL" />
      </geometry>
    </collision>
  </link>
  <joint
    name="index_joint_Link_r5"
    type="fixed">
    <origin
      xyz="0.015969 0.0093937 0"
      rpy="0 0 0" />
    <parent
      link="r_index_Link4" />
    <child
      link="r_index_Link5" />
    <axis
      xyz="0 0 0" />
  </joint>
  <link
    name="r_mid_Link">
    <inertial>
      <origin
        xyz="1.40734689794975E-06 0.000694753407640344 -0.00514190377968304"
        rpy="0 0 0" />
      <mass
        value="0.00431903652366697" />
      <inertia
        ixx="1.36153765292187E-06"
        ixy="9.79511055730686E-11"
        ixz="4.67011748284453E-12"
        iyy="2.52419454902548E-07"
        iyz="-1.32210483173002E-07"
        izz="1.38757795837307E-06" />
    </inertial>
    <visual>
      <origin
        xyz="0 0 0"
        rpy="0 0 0" />
      <geometry>
        <mesh
          filename="../meshes/r_mid_Link.STL" />
      </geometry>
      <material
        name="">
        <color
          rgba="0.792156862745098 0.819607843137255 0.933333333333333 1" />
      </material>
    </visual>
    <collision>
      <origin
        xyz="0 0 0"
        rpy="0 0 0" />
      <geometry>
        <mesh
          filename="../meshes/r_mid_Link.STL" />
      </geometry>
    </collision>
  </link>
  <joint
    name="mid_joint_Link_r"
    type="fixed">
    <origin
      xyz="-0.0103822553151064 0.0125051922308144 0.0713093829703847"
      rpy="1.65806266442309 0 1.5707963267949" />
    <parent
      link="right_hand_base_link" />
    <child
      link="r_mid_Link" />
    <axis
      xyz="0 0 0" />
  </joint>
  <link
    name="r_mid_Link1">
    <inertial>
      <origin
        xyz="3.36374291615149E-08 -0.000949758546365281 -0.00979761945009709"
        rpy="0 0 0" />
      <mass
        value="0.000753716553118287" />
      <inertia
        ixx="4.386053097916E-08"
        ixy="-3.32943076710991E-14"
        ixz="-1.25753824577688E-13"
        iyy="9.49698621336344E-08"
        iyz="-2.45771565647132E-09"
        izz="5.93127497638759E-08" />
    </inertial>
    <visual>
      <origin
        xyz="0 0 0"
        rpy="0 0 0" />
      <geometry>
        <mesh
          filename="../meshes/r_mid_Link1.STL" />
      </geometry>
      <material
        name="">
        <color
          rgba="0.792156862745098 0.819607843137255 0.933333333333333 1" />
      </material>
    </visual>
    <collision>
      <origin
        xyz="0 0 0"
        rpy="0 0 0" />
      <geometry>
        <mesh
          filename="../meshes/r_mid_Link1.STL" />
      </geometry>
    </collision>
  </link>
  <joint
    name="mid_joint_Link_r1"
    type="revolute">
    <origin
      xyz="0 0.02627 0.012021"
      rpy="0 0 0" />
    <parent
      link="r_mid_Link" />
    <child
      link="r_mid_Link1" />
    <axis
      xyz="0 0 -1" />
    <limit
      lower="-0.35"
      upper="0.35"
      effort="0"
      velocity="0" />
  </joint>
  <link
    name="r_mid_Link2">
    <inertial>
      <origin
        xyz="0.0248565660487101 -0.0064686956840581 -6.14072578129787E-05"
        rpy="0 0 0" />
      <mass
        value="0.00670640167039344" />
      <inertia
        ixx="2.7447947098352E-07"
        ixy="-5.34656206804511E-08"
        ixz="1.86377693304953E-09"
        iyy="1.64928295941372E-06"
        iyz="-4.9369088910234E-10"
        izz="1.53795926127141E-06" />
    </inertial>
    <visual>
      <origin
        xyz="0 0 0"
        rpy="0 0 0" />
      <geometry>
        <mesh
          filename="../meshes/r_mid_Link2.STL" />
      </geometry>
      <material
        name="">
        <color
          rgba="0.792156862745098 0.819607843137255 0.933333333333333 1" />
      </material>
    </visual>
    <collision>
      <origin
        xyz="0 0 0"
        rpy="0 0 0" />
      <geometry>
        <mesh
          filename="../meshes/r_mid_Link2.STL" />
      </geometry>
    </collision>
  </link>
  <joint
    name="mid_joint_Link_r2"
    type="revolute">
    <origin
      xyz="0 0 0"
      rpy="1.5708 0.085664 1.5708" />
    <parent
      link="r_mid_Link1" />
    <child
      link="r_mid_Link2" />
    <axis
      xyz="0 0 1" />
    <limit
      lower="0"
      upper="1.48"
      effort="0"
      velocity="0" />
  </joint>
  <link
    name="r_mid_Link3">
    <inertial>
      <origin
        xyz="0.0118307806735845 -0.00648694588441903 -0.00079616260307093"
        rpy="0 0 0" />
      <mass
        value="0.00348556469916572" />
      <inertia
        ixx="9.92805063224001E-08"
        ixy="2.41258687642837E-08"
        ixz="-5.74560039016165E-09"
        iyy="3.52536482867362E-07"
        iyz="1.97293601740165E-10"
        izz="3.29212828031843E-07" />
    </inertial>
    <visual>
      <origin
        xyz="0 0 0"
        rpy="0 0 0" />
      <geometry>
        <mesh
          filename="../meshes/r_mid_Link3.STL" />
      </geometry>
      <material
        name="">
        <color
          rgba="0.792156862745098 0.819607843137255 0.933333333333333 1" />
      </material>
    </visual>
    <collision>
      <origin
        xyz="0 0 0"
        rpy="0 0 0" />
      <geometry>
        <mesh
          filename="../meshes/r_mid_Link3.STL" />
      </geometry>
    </collision>
  </link>
  <joint
    name="mid_joint_Link_r3"
    type="revolute">
    <origin
      xyz="0.051996 -0.00027708 0"
      rpy="0 0 0.085664" />
    <parent
      link="r_mid_Link2" />
    <child
      link="r_mid_Link3" />
    <axis
      xyz="0 0 1" />
    <limit
      lower="0"
      upper="1.4"
      effort="0"
      velocity="0" />
  </joint>
  <link
    name="r_mid_Link4">
    <inertial>
      <origin
        xyz="0.0113404372697324 -0.00167958619198134 -0.000220244239396788"
        rpy="0 0 0" />
      <mass
        value="0.00286590326282753" />
      <inertia
        ixx="1.43022179570016E-07"
        ixy="1.98729010947097E-08"
        ixz="-6.94917459018936E-09"
        iyy="2.98349815549752E-07"
        iyz="5.48901986578988E-10"
        izz="2.23361577561831E-07" />
    </inertial>
    <visual>
      <origin
        xyz="0 0 0"
        rpy="0 0 0" />
      <geometry>
        <mesh
          filename="../meshes/r_mid_Link4.STL" />
      </geometry>
      <material
        name="">
        <color
          rgba="0.792156862745098 0.819607843137255 0.933333333333333 1" />
      </material>
    </visual>
    <collision>
      <origin
        xyz="0 0 0"
        rpy="0 0 0" />
      <geometry>
        <mesh
          filename="../meshes/r_mid_Link4.STL" />
      </geometry>
    </collision>
  </link>
  <joint
    name="mid_joint_Link_r4"
    type="revolute">
    <origin
      xyz="0.026928 -0.0076747 0"
      rpy="0 0 0" />
    <parent
      link="r_mid_Link3" />
    <child
      link="r_mid_Link4" />
    <axis
      xyz="0 0 1" />
    <limit
      lower="0"
      upper="1.4"
      effort="0"
      velocity="0" />
  </joint>
  <link
    name="r_mid_Link5">
    <inertial>
      <origin
        xyz="0.00181569960563313 -0.00401759470056587 -1.7394239911761E-06"
        rpy="0 0 0" />
      <mass
        value="0.000450710583141373" />
      <inertia
        ixx="1.88812291416604E-08"
        ixy="1.04173783141527E-08"
        ixz="1.05243210055251E-12"
        iyy="2.21563214884085E-08"
        iyz="-4.53245467039529E-12"
        izz="2.55181321608863E-08" />
    </inertial>
    <visual>
      <origin
        xyz="0 0 0"
        rpy="0 0 0" />
      <geometry>
        <mesh
          filename="../meshes/r_mid_Link5.STL" />
      </geometry>
      <material
        name="">
        <color
          rgba="0.792156862745098 0.819607843137255 0.933333333333333 1" />
      </material>
    </visual>

    <!-- Add fingertip sphere -->
    <visual>
      <origin xyz="0 0 0" rpy="0 0 0" /> <!-- Positioning the sphere slightly from the tip -->
      <geometry>
        <sphere radius="0.005" /> <!-- Radius of the sphere, 5mm -->
      </geometry>
      <material name="blue">
        <color rgba="0 0 1 1" /> <!-- Red color for the fingertip -->
      </material>
    </visual>

    <collision>
      <origin
        xyz="0 0 0"
        rpy="0 0 0" />
      <geometry>
        <mesh
          filename="../meshes/r_mid_Link5.STL" />
      </geometry>
    </collision>
  </link>
  <joint
    name="mid_joint_Link_r5"
    type="fixed">
    <origin
      xyz="0.0159685314889383 0.00939365856358672 0"
      rpy="0 0 0" />
    <parent
      link="r_mid_Link4" />
    <child
      link="r_mid_Link5" />
    <axis
      xyz="0 0 0" />
  </joint>
  <link
    name="r_ring_Link">
    <inertial>
      <origin
        xyz="1.4081463746568E-06 0.000694751167352098 -0.00514190259280253"
        rpy="0 0 0" />
      <mass
        value="0.00431903596206097" />
      <inertia
        ixx="1.36153753422029E-06"
        ixy="9.78712674448195E-11"
        ixz="4.71086666899664E-12"
        iyy="2.52419494869348E-07"
        iyz="-1.3221055399997E-07"
        izz="1.38757778737741E-06" />
    </inertial>
    <visual>
      <origin
        xyz="0 0 0"
        rpy="0 0 0" />
      <geometry>
        <mesh
          filename="../meshes/r_ring_Link.STL" />
      </geometry>
      <material
        name="">
        <color
          rgba="0.792156862745098 0.819607843137255 0.933333333333333 1" />
      </material>
    </visual>
    <collision>
      <origin
        xyz="0 0 0"
        rpy="0 0 0" />
      <geometry>
        <mesh
          filename="../meshes/r_ring_Link.STL" />
      </geometry>
    </collision>
  </link>
  <joint
    name="ring_joint_Link_r"
    type="fixed">
    <origin
      xyz="-0.0091687 -0.014221 0.066309"
      rpy="1.6581 0 1.6582" />
    <parent
      link="right_hand_base_link" />
    <child
      link="r_ring_Link" />
    <axis
      xyz="0 0 0" />
  </joint>
  <link
    name="r_ring_Link1">
    <inertial>
      <origin
        xyz="2.37358247223707E-08 -0.000949758224484995 -0.00979761991811526"
        rpy="0 0 0" />
      <mass
        value="0.000753716414191309" />
      <inertia
        ixx="4.38605328503131E-08"
        ixy="-2.46710673237958E-14"
        ixz="-1.01364693007023E-13"
        iyy="9.49698617614435E-08"
        iyz="-2.45771601251918E-09"
        izz="5.93127477633958E-08" />
    </inertial>
    <visual>
      <origin
        xyz="0 0 0"
        rpy="0 0 0" />
      <geometry>
        <mesh
          filename="../meshes/r_ring_Link1.STL" />
      </geometry>
      <material
        name="">
        <color
          rgba="0.792156862745098 0.819607843137255 0.933333333333333 1" />
      </material>
    </visual>
    <collision>
      <origin
        xyz="0 0 0"
        rpy="0 0 0" />
      <geometry>
        <mesh
          filename="../meshes/r_ring_Link1.STL" />
      </geometry>
    </collision>
  </link>
  <joint
    name="ring_joint_Link_r1"
    type="revolute">
    <origin
      xyz="0 0.02627 0.012021"
      rpy="0 0 0" />
    <parent
      link="r_ring_Link" />
    <child
      link="r_ring_Link1" />
    <axis
      xyz="0 0 -1" />
    <limit
      lower="-0.35"
      upper="0.35"
      effort="0"
      velocity="0" />
  </joint>
  <link
    name="r_ring_Link2">
    <inertial>
      <origin
        xyz="0.0248566382390737 -0.00646877533874726 -6.12887386269856E-05"
        rpy="0 0 0" />
      <mass
        value="0.0067064348432748" />
      <inertia
        ixx="2.74476666323832E-07"
        ixy="-5.34726783492085E-08"
        ixz="1.86744926076536E-09"
        iyy="1.64928770846785E-06"
        iyz="-4.96366436099556E-10"
        izz="1.53796806986171E-06" />
    </inertial>
    <visual>
      <origin
        xyz="0 0 0"
        rpy="0 0 0" />
      <geometry>
        <mesh
          filename="../meshes/r_ring_Link2.STL" />
      </geometry>
      <material
        name="">
        <color
          rgba="0.792156862745098 0.819607843137255 0.933333333333333 1" />
      </material>
    </visual>
    <collision>
      <origin
        xyz="0 0 0"
        rpy="0 0 0" />
      <geometry>
        <mesh
          filename="../meshes/r_ring_Link2.STL" />
      </geometry>
    </collision>
  </link>
  <joint
    name="ring_joint_Link_r2"
    type="revolute">
    <origin
      xyz="0 0 0"
      rpy="1.5708 0.085664 1.5708" />
    <parent
      link="r_ring_Link1" />
    <child
      link="r_ring_Link2" />
    <axis
      xyz="0 0 1" />
    <limit
      lower="0"
      upper="1.48"
      effort="0"
      velocity="0" />
  </joint>
  <link
    name="r_ring_Link3">
    <inertial>
      <origin
        xyz="0.0118307298664946 -0.00648704260697541 -0.000796133654823936"
        rpy="0 0 0" />
      <mass
        value="0.00348561291517494" />
      <inertia
        ixx="9.92834585384601E-08"
        ixy="2.41267862410674E-08"
        ixz="-5.74508054907317E-09"
        iyy="3.52541207017489E-07"
        iyz="1.97002319666101E-10"
        izz="3.29215822821692E-07" />
    </inertial>
    <visual>
      <origin
        xyz="0 0 0"
        rpy="0 0 0" />
      <geometry>
        <mesh
          filename="../meshes/r_ring_Link3.STL" />
      </geometry>
      <material
        name="">
        <color
          rgba="0.792156862745098 0.819607843137255 0.933333333333333 1" />
      </material>
    </visual>
    <collision>
      <origin
        xyz="0 0 0"
        rpy="0 0 0" />
      <geometry>
        <mesh
          filename="../meshes/r_ring_Link3.STL" />
      </geometry>
    </collision>
  </link>
  <joint
    name="ring_joint_Link_r3"
    type="revolute">
    <origin
      xyz="0.051996 -0.00027708 0"
      rpy="0 0 0.085664" />
    <parent
      link="r_ring_Link2" />
    <child
      link="r_ring_Link3" />
    <axis
      xyz="0 0 1" />
    <limit
      lower="0"
      upper="1.4"
      effort="0"
      velocity="0" />
  </joint>
  <link
    name="r_ring_Link4">
    <inertial>
      <origin
        xyz="0.0113403904097355 -0.00167959830494618 -0.000220240319862355"
        rpy="0 0 0" />
      <mass
        value="0.00286588485581286" />
      <inertia
        ixx="1.43021809770463E-07"
        ixy="1.98728275044481E-08"
        ixz="-6.94924248279532E-09"
        iyy="2.98348498308951E-07"
        iyz="5.4897755005092E-10"
        izz="2.23359872648577E-07" />
    </inertial>
    <visual>
      <origin
        xyz="0 0 0"
        rpy="0 0 0" />
      <geometry>
        <mesh
          filename="../meshes/r_ring_Link4.STL" />
      </geometry>
      <material
        name="">
        <color
          rgba="0.792156862745098 0.819607843137255 0.933333333333333 1" />
      </material>
    </visual>
    <collision>
      <origin
        xyz="0 0 0"
        rpy="0 0 0" />
      <geometry>
        <mesh
          filename="../meshes/r_ring_Link4.STL" />
      </geometry>
    </collision>
  </link>
  <joint
    name="ring_joint_Link_r4"
    type="revolute">
    <origin
      xyz="0.026928 -0.0076747 0"
      rpy="0 0 0" />
    <parent
      link="r_ring_Link3" />
    <child
      link="r_ring_Link4" />
    <axis
      xyz="0 0 1" />
    <limit
      lower="0"
      upper="1.4"
      effort="0"
      velocity="0" />
  </joint>
  <link
    name="r_ring_Link5">
    <inertial>
      <origin
        xyz="0.00181570080619201 -0.00401778531920312 -1.80091041671049E-06"
        rpy="0 0 0" />
      <mass
        value="0.000450714747271973" />
      <inertia
        ixx="1.88820708482565E-08"
        ixy="1.04176728214793E-08"
        ixz="1.5299220221432E-12"
        iyy="2.21560954057769E-08"
        iyz="-4.68235050476128E-12"
        izz="2.55189481762222E-08" />
    </inertial>
    <visual>
      <origin
        xyz="0 0 0"
        rpy="0 0 0" />
      <geometry>
        <mesh
          filename="../meshes/r_ring_Link5.STL" />
      </geometry>
      <material
        name="">
        <color
          rgba="0.792156862745098 0.819607843137255 0.933333333333333 1" />
      </material>
    </visual>

    <!-- Add fingertip sphere -->
    <visual>
      <origin xyz="0 0 0" rpy="0 0 0" /> <!-- Positioning the sphere slightly from the tip -->
      <geometry>
        <sphere radius="0.005" /> <!-- Radius of the sphere, 5mm -->
      </geometry>
      <material name="cyan">
        <color rgba="0 1 1 1" /> <!-- Red color for the fingertip -->
      </material>
    </visual>

    <collision>
      <origin
        xyz="0 0 0"
        rpy="0 0 0" />
      <geometry>
        <mesh
          filename="../meshes/r_ring_Link5.STL" />
      </geometry>
    </collision>
  </link>
  <joint
    name="ring_joint_Link_r5"
    type="fixed">
    <origin
      xyz="0.015968530891711 0.00939365572937095 0"
      rpy="0 0 0" />
    <parent
      link="r_ring_Link4" />
    <child
      link="r_ring_Link5" />
    <axis
      xyz="0 0 0" />
  </joint>
  <link
    name="r_little_Link">
    <inertial>
      <origin
        xyz="1.42050090018442E-06 0.000694714899473051 -0.00514189726990826"
        rpy="0 0 0" />
      <mass
        value="0.004319028054173" />
      <inertia
        ixx="1.36153454017162E-06"
        ixy="9.68833946461463E-11"
        ixz="4.84047453253449E-12"
        iyy="2.5241931490128E-07"
        iyz="-1.32210946895328E-07"
        izz="1.38757440201909E-06" />
    </inertial>
    <visual>
      <origin
        xyz="0 0 0"
        rpy="0 0 0" />
      <geometry>
        <mesh
          filename="../meshes/r_little_Link.STL" />
      </geometry>
      <material
        name="">
        <color
          rgba="0.792156862745098 0.819607843137255 0.933333333333333 1" />
      </material>
    </visual>
    <collision>
      <origin
        xyz="0 0 0"
        rpy="0 0 0" />
      <geometry>
        <mesh
          filename="../meshes/r_little_Link.STL" />
      </geometry>
    </collision>
  </link>
  <joint
    name="little_joint_Link_r"
    type="fixed">
    <origin
      xyz="-0.0056537 -0.040608 0.052309"
      rpy="1.6581 0 1.7453" />
    <parent
      link="right_hand_base_link" />
    <child
      link="r_little_Link" />
    <axis
      xyz="0 0 0" />
  </joint>
  <link
    name="r_little_Link1">
    <inertial>
      <origin
        xyz="2.15894949695539E-08 -0.000949758106968637 -0.00979761991353562"
        rpy="0 0 0" />
      <mass
        value="0.000753716389758328" />
      <inertia
        ixx="4.38605340572183E-08"
        ixy="-2.26679214914407E-14"
        ixz="-9.58623651606205E-14"
        iyy="9.49698625622802E-08"
        iyz="-2.45771620744386E-09"
        izz="5.93127473067216E-08" />
    </inertial>
    <visual>
      <origin
        xyz="0 0 0"
        rpy="0 0 0" />
      <geometry>
        <mesh
          filename="../meshes/r_little_Link1.STL" />
      </geometry>
      <material
        name="">
        <color
          rgba="0.792156862745098 0.819607843137255 0.933333333333333 1" />
      </material>
    </visual>
    <collision>
      <origin
        xyz="0 0 0"
        rpy="0 0 0" />
      <geometry>
        <mesh
          filename="../meshes/r_little_Link1.STL" />
      </geometry>
    </collision>
  </link>
  <joint
    name="little_joint_Link_r1"
    type="revolute">
    <origin
      xyz="0 0.02627 0.012021"
      rpy="0 0 0" />
    <parent
      link="r_little_Link" />
    <child
      link="r_little_Link1" />
    <axis
      xyz="0 0 -1" />
    <limit
      lower="-0.35"
      upper="0.35"
      effort="0"
      velocity="0" />
  </joint>
  <link
    name="r_little_Link2">
    <inertial>
      <origin
        xyz="0.0248564769107584 -0.00646876198903065 -6.13644604522678E-05"
        rpy="0 0 0" />
      <mass
        value="0.00670637145311763" />
      <inertia
        ixx="2.7447645450594E-07"
        ixy="-5.34712406453469E-08"
        ixz="1.86603038908778E-09"
        iyy="1.64927497768253E-06"
        iyz="-4.96714806591044E-10"
        izz="1.53795489026956E-06" />
    </inertial>
    <visual>
      <origin
        xyz="0 0 0"
        rpy="0 0 0" />
      <geometry>
        <mesh
          filename="../meshes/r_little_Link2.STL" />
      </geometry>
      <material
        name="">
        <color
          rgba="0.792156862745098 0.819607843137255 0.933333333333333 1" />
      </material>
    </visual>
    <collision>
      <origin
        xyz="0 0 0"
        rpy="0 0 0" />
      <geometry>
        <mesh
          filename="../meshes/r_little_Link2.STL" />
      </geometry>
    </collision>
  </link>
  <joint
    name="little_joint_Link_r2"
    type="revolute">
    <origin
      xyz="0 0 0"
      rpy="1.5708 0.085664 1.5708" />
    <parent
      link="r_little_Link1" />
    <child
      link="r_little_Link2" />
    <axis
      xyz="0 0 1" />
    <limit
      lower="0"
      upper="1.48"
      effort="0"
      velocity="0" />
  </joint>
  <link
    name="r_little_Link3">
    <inertial>
      <origin
        xyz="0.0118306833642413 -0.00648709457718372 -0.000796095260003515"
        rpy="0 0 0" />
      <mass
        value="0.00348563987405049" />
      <inertia
        ixx="9.92853938648564E-08"
        ixy="2.41275611037349E-08"
        ixz="-5.74450060429606E-09"
        iyy="3.52544949293293E-07"
        iyz="1.96646642894716E-10"
        izz="3.29218628340624E-07" />
    </inertial>
    <visual>
      <origin
        xyz="0 0 0"
        rpy="0 0 0" />
      <geometry>
        <mesh
          filename="../meshes/r_little_Link3.STL" />
      </geometry>
      <material
        name="">
        <color
          rgba="0.792156862745098 0.819607843137255 0.933333333333333 1" />
      </material>
    </visual>
    <collision>
      <origin
        xyz="0 0 0"
        rpy="0 0 0" />
      <geometry>
        <mesh
          filename="../meshes/r_little_Link3.STL" />
      </geometry>
    </collision>
  </link>
  <joint
    name="little_joint_Link_r3"
    type="revolute">
    <origin
      xyz="0.051996 -0.00027708 0"
      rpy="0 0 0.085664" />
    <parent
      link="r_little_Link2" />
    <child
      link="r_little_Link3" />
    <axis
      xyz="0 0 1" />
    <limit
      lower="0"
      upper="1.4"
      effort="0"
      velocity="0" />
  </joint>
  <link
    name="r_little_Link4">
    <inertial>
      <origin
        xyz="0.0113403185277721 -0.0016796111772258 -0.000220254538239317"
        rpy="0 0 0" />
      <mass
        value="0.00286585884070719" />
      <inertia
        ixx="1.43021563903845E-07"
        ixy="1.98727848616427E-08"
        ixz="-6.94900725101426E-09"
        iyy="2.98346315731695E-07"
        iyz="5.48937371833117E-10"
        izz="2.2335704802703E-07" />
    </inertial>
    <visual>
      <origin
        xyz="0 0 0"
        rpy="0 0 0" />
      <geometry>
        <mesh
          filename="../meshes/r_little_Link4.STL" />
      </geometry>
      <material
        name="">
        <color
          rgba="0.792156862745098 0.819607843137255 0.933333333333333 1" />
      </material>
    </visual>
    <collision>
      <origin
        xyz="0 0 0"
        rpy="0 0 0" />
      <geometry>
        <mesh
          filename="../meshes/r_little_Link4.STL" />
      </geometry>
    </collision>
  </link>
  <joint
    name="little_joint_Link_r4"
    type="revolute">
    <origin
      xyz="0.026928 -0.0076747 0"
      rpy="0 0 0" />
    <parent
      link="r_little_Link3" />
    <child
      link="r_little_Link4" />
    <axis
      xyz="0 0 1" />
    <limit
      lower="0"
      upper="1.4"
      effort="0"
      velocity="0" />
  </joint>
  <link
    name="r_little_Link5">
    <inertial>
      <origin
        xyz="0.00181874106074698 -0.00401838241116451 -1.86622306494466E-06"
        rpy="0 0 0" />
      <mass
        value="0.000450782444799643" />
      <inertia
        ixx="1.88768445250863E-08"
        ixy="1.04237526864194E-08"
        ixz="4.39707430489258E-12"
        iyy="2.21673292618662E-08"
        iyz="-4.81878102585485E-12"
        izz="2.55256969047996E-08" />
    </inertial>
    <visual>
      <origin
        xyz="0 0 0"
        rpy="0 0 0" />
      <geometry>
        <mesh
          filename="../meshes/r_little_Link5.STL" />
      </geometry>
      <material
        name="">
        <color
          rgba="0.792156862745098 0.819607843137255 0.933333333333333 1" />
      </material>
    </visual>

    <!-- Add fingertip sphere -->
    <visual>
      <origin xyz="0 0 0" rpy="0 0 0" /> <!-- Positioning the sphere slightly from the tip -->
      <geometry>
        <sphere radius="0.005" /> <!-- Radius of the sphere, 5mm -->
      </geometry>
      <material name="white">
        <color rgba="1 1 1 1" /> <!-- Red color for the fingertip -->
      </material>
    </visual>


    <collision>
      <origin
        xyz="0 0 0"
        rpy="0 0 0" />
      <geometry>
        <mesh
          filename="../meshes/r_little_Link5.STL" />
      </geometry>
    </collision>
  </link>
  <joint
    name="little_joint_Link_r5"
    type="fixed">
    <origin
      xyz="0.015969 0.0093937 0"
      rpy="0 0 0" />
    <parent
      link="r_little_Link4" />
    <child
      link="r_little_Link5" />
    <axis
      xyz="0 0 0" />
  </joint>
  <link
    name="r_thumb_Link">
    <inertial>
      <origin
        xyz="1.40230579113998E-06 0.000694866580801756 -0.0051418706859027"
        rpy="0 0 0" />
      <mass
        value="0.00431907969119648" />
      <inertia
        ixx="1.36154522060291E-06"
        ixy="9.82217148500541E-11"
        ixz="4.26043688365416E-12"
        iyy="2.52421751589446E-07"
        iyz="-1.32212410037383E-07"
        izz="1.38758491653064E-06" />
    </inertial>
    <visual>
      <origin
        xyz="0 0 0"
        rpy="0 0 0" />
      <geometry>
        <mesh
          filename="../meshes/r_thumb_Link.STL" />
      </geometry>
      <material
        name="">
        <color
          rgba="0.792156862745098 0.819607843137255 0.933333333333333 1" />
      </material>
    </visual>
    <collision>
      <origin
        xyz="0 0 0"
        rpy="0 0 0" />
      <geometry>
        <mesh
          filename="../meshes/r_thumb_Link.STL" />
      </geometry>
    </collision>
  </link>
  <joint
    name="thumb_joint_Link_r"
    type="fixed">
    <origin
      xyz="0.037455 0.038919 0.036487"
      rpy="1.0464 0.13138 -1.028" />
    <parent
      link="right_hand_base_link" />
    <child
      link="r_thumb_Link" />
    <axis
      xyz="0 0 0" />
  </joint>
  <link
    name="r_thumb_Link1">
    <inertial>
      <origin
        xyz="3.22604621766365E-08 -0.000949747733313883 -0.00979761254277101"
        rpy="0 0 0" />
      <mass
        value="0.000753717400818628" />
      <inertia
        ixx="4.38605857598433E-08"
        ixy="-3.40727981863525E-14"
        ixz="-1.23969753730443E-13"
        iyy="9.49699418347735E-08"
        iyz="-2.45773050203307E-09"
        izz="5.93127937062483E-08" />
    </inertial>
    <visual>
      <origin
        xyz="0 0 0"
        rpy="0 0 0" />
      <geometry>
        <mesh
          filename="../meshes/r_thumb_Link1.STL" />
      </geometry>
      <material
        name="">
        <color
          rgba="0.792156862745098 0.819607843137255 0.933333333333333 1" />
      </material>
    </visual>
    <collision>
      <origin
        xyz="0 0 0"
        rpy="0 0 0" />
      <geometry>
        <mesh
          filename="../meshes/r_thumb_Link1.STL" />
      </geometry>
    </collision>
  </link>
  <joint
    name="thumb_joint_Link_r1"
    type="revolute">
    <origin
      xyz="0 0.02627 0.012021"
      rpy="0 0 0" />
    <parent
      link="r_thumb_Link" />
    <child
      link="r_thumb_Link1" />
    <axis
      xyz="0 0 -1" />
    <limit
      lower="-0.35"
      upper="0.35"
      effort="0"
      velocity="0" />
  </joint>
  <link
    name="r_thumb_Link2">
    <inertial>
      <origin
        xyz="0.0248568497250459 -0.00646907137785471 -6.15035729938651E-05"
        rpy="0 0 0" />
      <mass
        value="0.00670654684315945" />
      <inertia
        ixx="2.74500895212551E-07"
        ixy="-5.34783564039926E-08"
        ixz="1.86231344794769E-09"
        iyy="1.64930255301144E-06"
        iyz="-4.95590499552161E-10"
        izz="1.53797397436188E-06" />
    </inertial>
    <visual>
      <origin
        xyz="0 0 0"
        rpy="0 0 0" />
      <geometry>
        <mesh
          filename="../meshes/r_thumb_Link2.STL" />
      </geometry>
      <material
        name="">
        <color
          rgba="0.792156862745098 0.819607843137255 0.933333333333333 1" />
      </material>
    </visual>
    <collision>
      <origin
        xyz="0 0 0"
        rpy="0 0 0" />
      <geometry>
        <mesh
          filename="../meshes/r_thumb_Link2.STL" />
      </geometry>
    </collision>
  </link>
  <joint
    name="thumb_joint_Link_r2"
    type="revolute">
    <origin
      xyz="0 0 0"
      rpy="1.5708 0.085664 1.5708" />
    <parent
      link="r_thumb_Link1" />
    <child
      link="r_thumb_Link2" />
    <axis
      xyz="0 0 1" />
    <limit
      lower="0"
      upper="1.48"
      effort="0"
      velocity="0" />
  </joint>
  <link
    name="r_thumb_Link3">
    <inertial>
      <origin
        xyz="0.0118298307091936 -0.00648739344702763 -0.00079626241049921"
        rpy="0 0 0" />
      <mass
        value="0.00348588809466915" />
      <inertia
        ixx="9.93154473247615E-08"
        ixy="2.41415494923171E-08"
        ixz="-5.7340116329816E-09"
        iyy="3.52589557924725E-07"
        iyz="1.96372787397589E-10"
        izz="3.29253526781633E-07" />
    </inertial>
    <visual>
      <origin
        xyz="0 0 0"
        rpy="0 0 0" />
      <geometry>
        <mesh
          filename="../meshes/r_thumb_Link3.STL" />
      </geometry>
      <material
        name="">
        <color
          rgba="0.792156862745098 0.819607843137255 0.933333333333333 1" />
      </material>
    </visual>
    <collision>
      <origin
        xyz="0 0 0"
        rpy="0 0 0" />
      <geometry>
        <mesh
          filename="../meshes/r_thumb_Link3.STL" />
      </geometry>
    </collision>
  </link>
  <joint
    name="thumb_joint_Link_r3"
    type="revolute">
    <origin
      xyz="0.051996 -0.00027708 0"
      rpy="0 0 0.085664" />
    <parent
      link="r_thumb_Link2" />
    <child
      link="r_thumb_Link3" />
    <axis
      xyz="0 0 1" />
    <limit
      lower="0"
      upper="1.4"
      effort="0"
      velocity="0" />
  </joint>
  <link
    name="r_thumb_Link4">
    <inertial>
      <origin
        xyz="0.0113402975536753 -0.00167951537757316 -0.000220343706938492"
        rpy="0 0 0" />
      <mass
        value="0.00286573032693069" />
      <inertia
        ixx="1.43012911875507E-07"
        ixy="1.9882460563681E-08"
        ixz="-6.94751166097923E-09"
        iyy="2.98332128482096E-07"
        iyz="5.48888145330615E-10"
        izz="2.23344603316087E-07" />
    </inertial>
    <visual>
      <origin
        xyz="0 0 0"
        rpy="0 0 0" />
      <geometry>
        <mesh
          filename="../meshes/r_thumb_Link4.STL" />
      </geometry>
      <material
        name="">
        <color
          rgba="0.792156862745098 0.819607843137255 0.933333333333333 1" />
      </material>
    </visual>
    <collision>
      <origin
        xyz="0 0 0"
        rpy="0 0 0" />
      <geometry>
        <mesh
          filename="../meshes/r_thumb_Link4.STL" />
      </geometry>
    </collision>
  </link>
  <joint
    name="thumb_joint_Link_r4"
    type="revolute">
    <origin
      xyz="0.026928 -0.0076747 0"
      rpy="0 0 0" />
    <parent
      link="r_thumb_Link3" />
    <child
      link="r_thumb_Link4" />
    <axis
      xyz="0 0 1" />
    <limit
      lower="0"
      upper="1.4"
      effort="0"
      velocity="0" />
  </joint>
  <link
    name="r_thumb_Link5">
    <inertial>
      <origin
        xyz="0.00181856047878773 -0.00401847227149434 -1.87882201413414E-06"
        rpy="0 0 0" />
      <mass
        value="0.00045076154121877" />
      <inertia
        ixx="1.88774181020804E-08"
        ixy="1.04240558774843E-08"
        ixz="4.26986738421168E-12"
        iyy="2.21670697484524E-08"
        iyz="-4.65019752884925E-12"
        izz="2.55261490684192E-08" />
    </inertial>
    <visual>
      <origin
        xyz="0 0 0"
        rpy="0 0 0" />
      <geometry>
        <mesh
          filename="../meshes/r_thumb_Link5.STL" />
      </geometry>
      <material
        name="">
        <color
          rgba="0.792156862745098 0.819607843137255 0.933333333333333 1" />
      </material>
    </visual>

    <!-- Add fingertip sphere -->
    <visual>
      <origin xyz="0 0 0" rpy="0 0 0" /> <!-- Positioning the sphere slightly from the tip -->
      <geometry>
        <sphere radius="0.005" /> <!-- Radius of the sphere, 5mm -->
      </geometry>
      <material name="red">
        <color rgba="1 0 0 1" /> <!-- Red color for the fingertip -->
      </material>
    </visual>
    
    <collision>
      <origin
        xyz="0 0 0"
        rpy="0 0 0" />
      <geometry>
        <mesh
          filename="../meshes/r_thumb_Link5.STL" />
      </geometry>
    </collision>
  </link>
  <joint
    name="thumb_joint_Link_r5"
    type="fixed">
    <origin
      xyz="0.015969 0.0093937 0"
      rpy="0 0 0" />
    <parent
      link="r_thumb_Link4" />
    <child
      link="r_thumb_Link5" />
    <axis
      xyz="0 0 0" />
  </joint>









</robot>